<mujoco>
    <compiler angle="degree" coordinate="global"/>
    <option>
        <flag gravity="disable" constraint="disable"/>
    </option>
    <!--
    <asset>
        <texture builtin="gradient" height="100" rgb1="1 1 1" rgb2="0 0 0" type="skybox" width="100"/>
        <texture builtin="flat" height="1278" mark="cross" markrgb="1 1 1" name="texgeom" random="0.01" rgb1="0.8 0.6 0.4" rgb2="0.8 0.6 0.4" type="cube" width="127"/>
        <texture builtin="checker" height="100" name="texplane" rgb1="0.8 0.8 0.8" rgb2="0.8 0.8 0.8" type="2d" width="100"/>
        <material name="MatPlane" reflectance="0.5" shininess="1" specular="1" texrepeat="60 60" texture="texplane"/>
        <material name="geom" texture="texgeom" texuniform="true"/>
    </asset>
    -->
    <visual>
        <rgba joint="0 1 0 1"/>
    </visual>
    <worldbody>
        <camera name="world_cam_x" mode="fixed" pos="5 0.5 0.5" quat="1 0 0 -1"/>
        <camera name="world_cam_y" mode="fixed" pos="0 -5 0.5"/>
        <camera name="world_cam_z" mode="fixed" pos="0 0 5"/>
      <light cutoff="100" diffuse="1 1 1" dir="0 0 -1.3" directional="true" exponent="1" pos="0 0 1.3" specular=".1 .1 .1"/>
      <!--
      <geom conaffinity="1" condim="3" material="MatPlane" name="floor" pos="0 0 0" rgba="0.8 0.9 0.8 1" size="40 40 40" type="plane"/>
      -->
      <body name="pointer" pos="0 1 0">
          <inertial pos="0 0 0" mass="1" diaginertia="0.001 0.001 0.001"/>
          <geom name="pointer_dot" size="0.05 0.05 0.05" rgba="0 0 1 1" pos="0 0 0" type="sphere"/>
          <joint name="pointer:jointx" type="hinge" pos="0 -5 1" axis="1 0 0"/>
          <joint name="pointer:jointz" type="hinge" pos="0 -5 1" axis="0 0 1"/>
      </body>
      <camera name="cam" mode="targetbody" target="pointer" pos="0 -6 1"/>
      <body name="rod" pos="0 0 2.0">
          <geom name="main_body" size="0.05 0.05 0.5" rgba="1 0 0 1" type="box"/>
      </body>
        <!--
      <body name="axes" pos="0 0 0">
          <geom name="zerox" fromto="0 0 0 1 0 0" rgba="0 1 1 1" size="0.05 0.05 0.05" type="capsule"/>
          <geom name="zeroy" fromto="0 0 0 0 1 0" rgba="1 0 1 1" size="0.05 0.05 0.05" type="capsule"/>
          <geom name="zeroz" fromto="0 0 0 0 0 1" rgba="1 1 0 1" size="0.05 0.05 0.05" type="capsule"/>
      </body>
      -->
  </worldbody>
    <actuator>
        <position ctrllimited="true" ctrlrange="-0.1 0.1" joint="pointer:jointx" kp="300" name="pointer:jointx" user="1" gear="0.1 0 0 0 0 0"/>
        <position ctrllimited="true" ctrlrange="-0.1 0.1" joint="pointer:jointz" kp="300" name="pointer:jointz" user="1" gear="0.1 0 0 0 0 0"/>
    </actuator>
</mujoco>
